Workbook

Sheet Ausschreibung
B2: Ausschreibung und Zeitplan
B3: 21. ERGOCUP Neckarelz
B4: Rennen | C4: Wett-bewerb | D4: Startzeit (erstes Abteil) | E4: Klasse | F4: Gewichtsklasse | G4: Alter | H4: Jahrgang | I4: Strecke | K4: Zeitfenster | M4: von | N4: bis
B5: 1 | C5: Ergocup | D5: =M5 -> 0.375 | E5: Masters A-H, weiblich | F5: - | G5: 27 und älter | H5: 1991 und älter | I5: 30 min. | K5: 40 | L5: min | M5: 0.375 | N5: =M5+O5 -> 0.40277778 | O5: =K5/24/60 -> 0.027777778
B6: 2 | C6: Ergocup | D6: =M6 -> 0.40277778 | E6: Masters A-H, männlich | F6: - | G6: 27 und älter | H6: 1991 und älter | I6: 30 min. | K6: 120 | L6: min | M6: =N5 -> 0.40277778 | N6: =M6+O6 -> 0.48611111 | O6: =K6/24/60 -> 0.083333333
B7: 3 | C7: Ergocup | D7: =M7 -> 0.48611111 | E7: Jungen U14 | F7: Lgw. bis 50 kg | G7: 13 und jünger | H7: 2005 und jünger | I7: 1000 m | K7: 8 | L7: min | M7: =N6 -> 0.48611111 | N7: =M7+O7 -> 0.49166667 | O7: =K7/24/60 -> 0.0055555556
B8: 4 | C8: Ergocup | D8: =M8 -> 0.49166667 | E8: Jungen U14 | F8: - | G8: 13 und jünger | H8: 2005 und jünger | I8: 1000 m | K8: 16 | L8: min | M8: =N7 -> 0.49166667 | N8: =M8+O8 -> 0.50277778 | O8: =K8/24/60 -> 0.011111111
B9: 5 | C9: Ergocup | D9: =M9 -> 0.50277778 | E9: Mädchen U14 | F9: Lgw. bis 50 kg | G9: 13 und jünger | H9: 2005 und jünger | I9: 1000 m | K9: 8 | L9: min | M9: =N8 -> 0.50277778 | N9: =M9+O9 -> 0.50833333 | O9: =K9/24/60 -> 0.0055555556
B10: 6 | C10: Ergocup | D10: =M10 -> 0.50833333 | E10: Mädchen U14 | F10: - | G10: 13 und jünger | H10: 2005 und jünger | I10: 1000 m | K10: 8 | L10: min | M10: =N9 -> 0.50833333 | N10: =M10+O10 -> 0.51388889 | O10: =K10/24/60 -> 0.0055555556
B11: 7 | C11: Ergocup | D11: =M11 -> 0.51388889 | E11: Mädchen U15 | F11: Lgw. bis 52,5 kg | G11: 14 | H11: 2004 | I11: 1000 m | K11: 8 | L11: min | M11: =N10 -> 0.51388889 | N11: =M11+O11 -> 0.51944444 | O11: =K11/24/60 -> 0.0055555556
B12: 8 | C12: Ergocup | D12: =M12 -> 0.51944444 | E12: Mädchen U15 | F12: - | G12: 14 | H12: 2004 | I12: 1000 m | K12: 8 | L12: min | M12: =N11 -> 0.51944444 | N12: =M12+O12 -> 0.525 | O12: =K12/24/60 -> 0.0055555556
B13: 9 | C13: Ergocup | D13: =M13 -> 0.525 | E13: Jungen U15 | F13: Lgw. bis 55 kg | G13: 14 | H13: 2004 | I13: 1000 m | K13: 16 | L13: min | M13: =N12 -> 0.525 | N13: =M13+O13 -> 0.53611111 | O13: =K13/24/60 -> 0.011111111
B14: 10 | C14: Ergocup | D14: =M14 -> 0.53611111 | E14: Jungen U15 | F14: - | G14: 14 | H14: 2004 | I14: 1000 m | K14: 16 | L14: min | M14: =N13 -> 0.53611111 | N14: =M14+O14 -> 0.54722222 | O14: =K14/24/60 -> 0.011111111
B15: =M15 -> 0.54722222 | C15: bis | D15: =N15 -> 0.56805556 | E15: Siegerehrung ERGOCUP Teil 1 und Pause | K15: 30 | L15: min | M15: =N14 -> 0.54722222 | N15: =M15+O15 -> 0.56805556 | O15: =K15/24/60 -> 0.020833333
B16: Rennen | C16: Wett-bewerb | D16: Startzeit | E16: Klasse | F16: Gewichtsklasse | G16: Alter | H16: Jahrgang | I16: Strecke | K16: Zeitfenster | M16: von | N16: bis
B17: 11 | C17: Ergocup | D17: =M17 -> 0.56805556 | E17: Juniorinnen B U17 | F17: Lgw. bis 57,5kg | G17: 15-16 | H17: 2003 und 2002 | I17: 1500 m | K17: 12 | L17: min | M17: =N15 -> 0.56805556 | N17: =M17+O17 -> 0.57638889 | O17: =K17/24/60 -> 0.0083333333
B18: 12 | C18: Ergocup | D18: =M18 -> 0.57638889 | E18: Juniorinnen B U17 | F18: - | G18: 15-16 | H18: 2003 und 2002 | I18: 1500 m | K18: 24 | L18: min | M18: =N17 -> 0.57638889 | N18: =M18+O18 -> 0.59305556 | O18: =K18/24/60 -> 0.016666667
B19: 13 | C19: Ergocup | D19: =M19 -> 0.59305556 | E19: Junioren B U17 | F19: Lgw. bis 67,5kg | G19: 15-16 | H19: 2003 und 2002 | I19: 1500 m | K19: 24 | L19: min | M19: =N18 -> 0.59305556 | N19: =M19+O19 -> 0.60972222 | O19: =K19/24/60 -> 0.016666667
B20: 14 | C20: Ergocup | D20: =M20 -> 0.60972222 | E20: Junioren B U17 | F20: - | G20: 15-16 | H20: 2003 und 2002 | I20: 1500 m | K20: 12 | L20: min | M20: =N19 -> 0.60972222 | N20: =M20+O20 -> 0.61805556 | O20: =K20/24/60 -> 0.0083333333
B21: 15 | C21: Ergocup | D21: =M21 -> 0.61805556 | E21: Sprint weiblich | F21: - | G21: offen | H21: offen | I21: 350 m | K21: 0 | L21: min | M21: =N20 -> 0.61805556 | N21: =M21+O21 -> 0.61805556 | O21: =K21/24/60 -> 0
B22: 16 | C22: Ergocup | D22: =M22 -> 0.61805556 | E22: Sprint männlich | F22: - | G22: offen | H22: offen | I22: 350 m | K22: 4 | L22: min | M22: =N21 -> 0.61805556 | N22: =M22+O22 -> 0.62083333 | O22: =K22/24/60 -> 0.0027777778
B23: 17 | C23: Ergocup | D23: =M23 -> 0.62083333 | E23: Juniorinnen A U19 | F23: LGW. bis 60 kg | G23: 17-18 | H23: 2001 und 2000 | I23: 2000 m | K23: 0 | L23: min | M23: =N22 -> 0.62083333 | N23: =M23+O23 -> 0.62083333 | O23: =K23/24/60 -> 0
B24: =B23+1 -> 18 | C24: Ergocup | D24: =M24 -> 0.62083333 | E24: Juniorinnen A U19 | F24: - | G24: 17-18 | H24: 2001 und 2000 | I24: 2000 m | K24: 15 | L24: min | M24: =N23 -> 0.62083333 | N24: =M24+O24 -> 0.63125 | O24: =K24/24/60 -> 0.010416667
B25: =B24+1 -> 19 | C25: Ergocup | D25: =M25 -> 0.63125 | E25: Junioren A U19 | F25: LGW. bis 70 kg | G25: 17-18 | H25: 2001 und 2000 | I25: 2000 m | K25: 0 | L25: min | M25: =N24 -> 0.63125 | N25: =M25+O25 -> 0.63125 | O25: =K25/24/60 -> 0
B26: =B25+1 -> 20 | C26: Ergocup | D26: =M26 -> 0.63125 | E26: Junioren A U19 | F26: - | G26: 17-18 | H26: 2001 und 2000 | I26: 2000 m | K26: 15 | L26: min | M26: =N25 -> 0.63125 | N26: =M26+O26 -> 0.64166667 | O26: =K26/24/60 -> 0.010416667
B27: =B26+1 -> 21 | C27: Ergocup | D27: =M27 -> 0.64166667 | E27: Seniorinnen A | F27: LGW. bis 61 kg | G27: 19 und älter | H27: 1999 und älter | I27: 2000 m | K27: 0 | L27: min | M27: =N26 -> 0.64166667 | N27: =M27+O27 -> 0.64166667 | O27: =K27/24/60 -> 0
B28: =B27+1 -> 22 | C28: Ergocup | D28: =M28 -> 0.64166667 | E28: Seniorinnen A | F28: - | G28: 19 und älter | H28: 1999 und älter | I28: 2000 m | K28: 15 | L28: min | M28: =N27 -> 0.64166667 | N28: =M28+O28 -> 0.65208333 | O28: =K28/24/60 -> 0.010416667
B29: =B28+1 -> 23 | C29: Ergocup | D29: =M29 -> 0.65208333 | E29: Senioren A | F29: LGW. bis 75 kg | G29: 19 und älter | H29: 1999 und älter | I29: 2000 m | K29: 0 | L29: min | M29: =N28 -> 0.65208333 | N29: =M29+O29 -> 0.65208333 | O29: =K29/24/60 -> 0
B30: =B29+1 -> 24 | C30: Ergocup | D30: =M30 -> 0.65208333 | E30: Senioren A | F30: - | G30: 19 und älter | H30: 1999 und älter | I30: 2000 m | K30: 15 | L30: min | M30: =N29 -> 0.65208333 | N30: =M30+O30 -> 0.6625 | O30: =K30/24/60 -> 0.010416667
B31: =B30+1 -> 25 | C31: Ergocup | D31: =M31 -> 0.6625 | E31: Masters A-H, männlich | F31: - | G31: 27 und älter | H31: 1991 und älter | I31: 2000 m | K31: 15 | L31: min | M31: =N30 -> 0.6625 | N31: =M31+O31 -> 0.67291667 | O31: =K31/24/60 -> 0.010416667
B32: =B31+1 -> 26 | C32: Ergocup | D32: =M32 -> 0.67291667 | E32: Masters A-H, weiblich | F32: - | G32: 27 und älter | H32: 1991 und älter | I32: 2000 m | K32: 0 | L32: min | M32: =N31 -> 0.67291667 | N32: =M32+O32 -> 0.67291667 | O32: =K32/24/60 -> 0
B33: =B32+1 -> 27 | C33: Ergocup | D33: =M33 -> 0.67291667 | E33: Masters A-H, männlich | F33: - | G33: 27 und älter | H33: 1991 und älter | I33: 1000 m | K33: 0 | L33: min | M33: =N32 -> 0.67291667 | N33: =M33+O39 -> 0.67291667
B34: =B33+1 -> 28 | C34: Ergocup | D34: =M34 -> 0.67291667 | E34: Masters A-H, weiblich | F34: - | G34: 27 und älter | H34: 1991 und älter | I34: 1000 m | K34: 10 | L34: min | M34: =N33 -> 0.67291667 | N34: =M34+O40 -> 0.67986111
B35: =B34+1 -> 29 | C35: Ergocup | D35: =M35 -> 0.67986111 | E35: Mannschaft offen - 2 Personen | F35: - | G35: offen | H35: offen | I35: 5000 m | K35: 25 | L35: min | M35: =N34 -> 0.67986111 | N35: =M35+O41 -> 0.69722222
B36: =N35 -> 0.69722222 | C36: bis | D36: =N36 -> 0.71805556 | E36: Siegerehrung ERGOCUP Teil 2, Gesamtsieger ERGOCUP | K36: 30 | L36: min | M36: =N35 -> 0.69722222 | N36: =M36+O42 -> 0.71805556
O39: =K33/24/60 -> 0
O40: =K34/24/60 -> 0.0069444444
O41: =K35/24/60 -> 0.017361111
O42: =K36/24/60 -> 0.020833333

Sheet Eingabe Meldungen
A1: Rennen | B1: Wettbewerb | C1: Name | D1: Vorname | E1: Altersklasse | F1: Klasse | G1: Altersgrenze | H1: Jahrgang | I1: Strecke | J1: Verein | K1: Nachmeldung
A2: 2 | C2: Gocke | D2: Eberhard | E2: =VLOOKUP(A2,Ausschreibung!$B$4:$I$35,4,FALSE) -> Masters A-H, männlich | F2: J | G2: =VLOOKUP(A2,Ausschreibung!$B$4:$I$35,6,FALSE) -> 27 und älter | H2: 1940 | I2: =VLOOKUP(A2,Ausschreibung!$B$4:$I$35,8,FALSE) -> 30 min. | J2: RC Neptun Neckarelz | L2: =2020-H2 -> 80
A3: 28 | C3: Gocke | D3: Eberhard | E3: =VLOOKUP(A3,Ausschreibung!$B$4:$I$35,4,FALSE) -> Masters A-H, weiblich | F3: J | G3: =VLOOKUP(A3,Ausschreibung!$B$4:$I$35,6,FALSE) -> 27 und älter | H3: 1940 | I3: =VLOOKUP(A3,Ausschreibung!$B$4:$I$35,8,FALSE) -> 1000 m | J3: RC Neptun Neckarelz | L3: =2020-H3 -> 80
A4: 25 | C4: Sommer | D4: Christian | E4: =VLOOKUP(A4,Ausschreibung!$B$4:$I$35,4,FALSE) -> Masters A-H, männlich | F4: I | G4: =VLOOKUP(A4,Ausschreibung!$B$4:$I$35,6,FALSE) -> 27 und älter | H4: 1942 | I4: =VLOOKUP(A4,Ausschreibung!$B$4:$I$35,8,FALSE) -> 2000 m | J4: USV TU Dresden | L4: =2020-H4 -> 78
A5: 2 | C5: Schultheiß | D5: Günther | E5: =VLOOKUP(A5,Ausschreibung!$B$4:$I$35,4,FALSE) -> Masters A-H, männlich | F5: J | G5: =VLOOKUP(A5,Ausschreibung!$B$4:$I$35,6,FALSE) -> 27 und älter | H5: 1942 | I5: =VLOOKUP(A5,Ausschreibung!$B$4:$I$35,8,FALSE) -> 30 min. | J5: RC Neptun Neckarelz | L5: =2020-H5 -> 78
A6: 2 | C6: Diem | D6: Werner | E6: =VLOOKUP(A6,Ausschreibung!$B$4:$I$35,4,FALSE) -> Masters A-H, männlich | F6: H | G6: =VLOOKUP(A6,Ausschreibung!$B$4:$I$35,6,FALSE) -> 27 und älter | H6: 1943 | I6: =VLOOKUP(A6,Ausschreibung!$B$4:$I$35,8,FALSE) -> 30 min. | J6: RC Neptun Neckarelz | L6: =2020-H6 -> 77
A7: 2 | C7: Schmiedeknecht | D7: Helmut | E7: =VLOOKUP(A7,Ausschreibung!$B$4:$I$35,4,FALSE) -> Masters A-H, männlich | F7: H | G7: =VLOOKUP(A7,Ausschreibung!$B$4:$I$35,6,FALSE) -> 27 und älter | H7: 1947 | I7: =VLOOKUP(A7,Ausschreibung!$B$4:$I$35,8,FALSE) -> 30 min. | J7: Ruderverein Bad Wimpfen | L7: =2020-H7 -> 73
A8: 28 | C8: Schmiedeknecht | D8: Helmut | E8: =VLOOKUP(A8,Ausschreibung!$B$4:$I$35,4,FALSE) -> Masters A-H, weiblich | F8: H | G8: =VLOOKUP(A8,Ausschreibung!$B$4:$I$35,6,FALSE) -> 27 und älter | H8: 1947 | I8: =VLOOKUP(A8,Ausschreibung!$B$4:$I$35,8,FALSE) -> 1000 m | J8: Ruderverein Bad Wimpfen | L8: =2020-H8 -> 73
A9: 2 | C9: Vollmer | D9: Gerhard | E9: =VLOOKUP(A9,Ausschreibung!$B$4:$I$35,4,FALSE) -> Masters A-H, männlich | F9: H | G9: =VLOOKUP(A9,Ausschreibung!$B$4:$I$35,6,FALSE) -> 27 und älter | H9: 1948 | I9: =VLOOKUP(A9,Ausschreibung!$B$4:$I$35,8,FALSE) -> 30 min. | J9: HRG Schwaben | L9: =2020-H9 -> 72
A10: 2 | C10: Schmidt | D10: Rolf | E10: =VLOOKUP(A10,Ausschreibung!$B$4:$I$35,4,FALSE) -> Masters A-H, männlich | F10: H | G10: =VLOOKUP(A10,Ausschreibung!$B$4:$I$35,6,FALSE) -> 27 und älter | H10: 1950 | I10: =VLOOKUP(A10,Ausschreibung!$B$4:$I$35,8,FALSE) -> 30 min. | J10: Marbacher Ruderverein | L10: =2020-H10 -> 70
A11: 2 | C11: Rentz | D11: Jürgen | E11: =VLOOKUP(A11,Ausschreibung!$B$4:$I$35,4,FALSE) -> Masters A-H, männlich | F11: G | G11: =VLOOKUP(A11,Ausschreibung!$B$4:$I$35,6,FALSE) -> 27 und älter | H11: 1955 | I11: =VLOOKUP(A11,Ausschreibung!$B$4:$I$35,8,FALSE) -> 30 min. | J11: Marbacher Ruderverein | L11: =2020-H11 -> 65
A12: 2 | C12: Klinge | D12: Achim | E12: =VLOOKUP(A12,Ausschreibung!$B$4:$I$35,4,FALSE) -> Masters A-H, männlich | F12: F | G12: =VLOOKUP(A12,Ausschreibung!$B$4:$I$35,6,FALSE) -> 27 und älter | H12: 1957 | I12: =VLOOKUP(A12,Ausschreibung!$B$4:$I$35,8,FALSE) -> 30 min. | J12: SSG Bensheim | L12: =2020-H12 -> 63
A13: 2 | C13: Köhler | D13: Bernhard | E13: =VLOOKUP(A13,Ausschreibung!$B$4:$I$35,4,FALSE) -> Masters A-H, männlich | F13: F | G13: =VLOOKUP(A13,Ausschreibung!$B$4:$I$35,6,FALSE) -> 27 und älter | H13: 1958 | I13: =VLOOKUP(A13,Ausschreibung!$B$4:$I$35,8,FALSE) -> 30 min. | J13: Fitness Oase in Regen | L13: =2020-H13 -> 62
... A19: 28 | C19: Kunz | D19: Gert | E19: =VLOOKUP(A19,Ausschreibung!$B$4:$I$35,4,FALSE) -> Masters A-H, weiblich | F19: J | G19: =VLOOKUP(A19,Ausschreibung!$B$4:$I$35,6,FALSE) -> 27 und älter | H19: 1940 | I19: =VLOOKUP(A19,Ausschreibung!$B$4:$I$35,8,FALSE) -> 1000 m | J19: USV TU Dresden | L19: =2020-H19 -> 80
A20: 2 | B20: =VLOOKUP(A20,[1]Ausschreibung!$B$4:$I$35,2,FALSE) -> Ergocup | C20: Marx | D20: Johannes | E20: =VLOOKUP(A20,Ausschreibung!$B$4:$I$35,4,FALSE) -> Masters A-H, männlich | F20: E | G20: =VLOOKUP(A20,Ausschreibung!$B$4:$I$35,6,FALSE) -> 27 und älter | H20: 1962 | I20: =VLOOKUP(A20,Ausschreibung!$B$4:$I$35,8,FALSE) -> 30 min. | J20: RC Neptun Neckarelz | L20: =2020-H20 -> 58
A21: 2 | C21: Reinert | D21: Gerhard | E21: =VLOOKUP(A21,Ausschreibung!$B$4:$I$35,4,FALSE) -> Masters A-H, männlich | F21: E | G21: =VLOOKUP(A21,Ausschreibung!$B$4:$I$35,6,FALSE) -> 27 und älter | H21: 1964 | I21: =VLOOKUP(A21,Ausschreibung!$B$4:$I$35,8,FALSE) -> 30 min. | J21: HRG Schwaben | L21: =2020-H21 -> 56
A22: 1 | C22: Schmidt | D22: Henriette | E22: =VLOOKUP(A22,Ausschreibung!$B$4:$I$35,4,FALSE) -> Masters A-H, weiblich | F22: D | G22: =VLOOKUP(A22,Ausschreibung!$B$4:$I$35,6,FALSE) -> 27 und älter | H22: 1965 | I22: =VLOOKUP(A22,Ausschreibung!$B$4:$I$35,8,FALSE) -> 30 min. | J22: Marbacher Ruderverein | L22: =2020-H22 -> 55
A23: 1 | C23: Young | D23: Susan | E23: =VLOOKUP(A23,Ausschreibung!$B$4:$I$35,4,FALSE) -> Masters A-H, weiblich | F23: D | G23: =VLOOKUP(A23,Ausschreibung!$B$4:$I$35,6,FALSE) -> 27 und älter | H23: 1965 | I23: =VLOOKUP(A23,Ausschreibung!$B$4:$I$35,8,FALSE) -> 30 min. | J23: Sub7 IRC | L23: =2020-H23 -> 55
A24: 2 | C24: Marion | D24: Markus | E24: =VLOOKUP(A24,Ausschreibung!$B$4:$I$35,4,FALSE) -> Masters A-H, männlich | F24: D | G24: =VLOOKUP(A24,Ausschreibung!$B$4:$I$35,6,FALSE) -> 27 und älter | H24: 1966 | I24: =VLOOKUP(A24,Ausschreibung!$B$4:$I$35,8,FALSE) -> 30 min. | J24: ErgoRudern Saarlouis | L24: =2020-H24 -> 54
A25: 1 | C25: Breitenbücher | D25: Heike | E25: =VLOOKUP(A25,Ausschreibung!$B$4:$I$35,4,FALSE) -> Masters A-H, weiblich | F25: D | G25: =VLOOKUP(A25,Ausschreibung!$B$4:$I$35,6,FALSE) -> 27 und älter | H25: 1967 | I25: =VLOOKUP(A25,Ausschreibung!$B$4:$I$35,8,FALSE) -> 30 min. | J25: Marbacher Ruderverein | L25: =2020-H25 -> 53
A26: 28 | C26: Öynhausen | D26: Jörg | E26: =VLOOKUP(A26,Ausschreibung!$B$4:$I$35,4,FALSE) -> Masters A-H, weiblich | F26: D | G26: =VLOOKUP(A26,Ausschreibung!$B$4:$I$35,6,FALSE) -> 27 und älter | H26: 1967 | I26: =VLOOKUP(A26,Ausschreibung!$B$4:$I$35,8,FALSE) -> 1000 m | J26: HRG Schwaben | L26: =2020-H26 -> 53
A27: 28 | C27: Heszler | D27: Peter | E27: =VLOOKUP(A27,Ausschreibung!$B$4:$I$35,4,FALSE) -> Masters A-H, weiblich | F27: D | G27: =VLOOKUP(A27,Ausschreibung!$B$4:$I$35,6,FALSE) -> 27 und älter | H27: 1967 | I27: =VLOOKUP(A27,Ausschreibung!$B$4:$I$35,8,FALSE) -> 1000 m | J27: RC Nürtingen | L27: =2020-H27 -> 53
A28: 2 | C28: Grünewald | D28: Christoph | E28: =VLOOKUP(A28,Ausschreibung!$B$4:$I$35,4,FALSE) -> Masters A-H, männlich | F28: D | G28: =VLOOKUP(A28,Ausschreibung!$B$4:$I$35,6,FALSE) -> 27 und älter | H28: 1968 | I28: =VLOOKUP(A28,Ausschreibung!$B$4:$I$35,8,FALSE) -> 30 min. | J28: Marbacher Ruderverein | L28: =2020-H28 -> 52
A29: 2 | C29: Rottler | D29: Christoph | E29: =VLOOKUP(A29,Ausschreibung!$B$4:$I$35,4,FALSE) -> Masters A-H, männlich | F29: D | G29: =VLOOKUP(A29,Ausschreibung!$B$4:$I$35,6,FALSE) -> 27 und älter | H29: 1968 | I29: =VLOOKUP(A29,Ausschreibung!$B$4:$I$35,8,FALSE) -> 30 min. | J29: HRG Schwaben | L29: =2020-H29 -> 52
A30: 2 | C30: Grün | D30: Michael | E30: =VLOOKUP(A30,Ausschreibung!$B$4:$I$35,4,FALSE) -> Masters A-H, männlich | F30: D | G30: =VLOOKUP(A30,Ausschreibung!$B$4:$I$35,6,FALSE) -> 27 und älter | H30: 1968 | I30: =VLOOKUP(A30,Ausschreibung!$B$4:$I$35,8,FALSE) -> 30 min. | J30: HRG Schwaben | L30: =2020-H30 -> 52
A31: 25 | C31: Grün | D31: Michael | E31: =VLOOKUP(A31,Ausschreibung!$B$4:$I$35,4,FALSE) -> Masters A-H, männlich | F31: D | G31: =VLOOKUP(A31,Ausschreibung!$B$4:$I$35,6,FALSE) -> 27 und älter | H31: 1968 | I31: =VLOOKUP(A31,Ausschreibung!$B$4:$I$35,8,FALSE) -> 2000 m | J31: HRG Schwaben | L31: =2020-H31 -> 52
A32: 2 | C32: Demmer | D32: Patrick | E32: =VLOOKUP(A32,Ausschreibung!$B$4:$I$35,4,FALSE) -> Masters A-H, männlich | F32: D | G32: =VLOOKUP(A32,Ausschreibung!$B$4:$I$35,6,FALSE) -> 27 und älter | H32: 1969 | I32: =VLOOKUP(A32,Ausschreibung!$B$4:$I$35,8,FALSE) -> 30 min. | J32: HRG Schwaben | L32: =2020-H32 -> 51
... A43: 28 | C43: Rebmann | D43: Sebastian | E43: =VLOOKUP(A43,Ausschreibung!$B$4:$I$35,4,FALSE) -> Masters A-H, weiblich | F43: C | G43: =VLOOKUP(A43,Ausschreibung!$B$4:$I$35,6,FALSE) -> 27 und älter | H43: 1976 | I43: =VLOOKUP(A43,Ausschreibung!$B$4:$I$35,8,FALSE) -> 1000 m | J43: Marbacher Ruderverein | L43: =2020-H43 -> 44
A44: 25 | B44: =VLOOKUP(A44,[1]Ausschreibung!$B$4:$I$35,2,FALSE) -> Ergocup | C44: Marx | D44: Johannes | E44: =VLOOKUP(A44,Ausschreibung!$B$4:$I$35,4,FALSE) -> Masters A-H, männlich | F44: E | G44: =VLOOKUP(A44,Ausschreibung!$B$4:$I$35,6,FALSE) -> 27 und älter | H44: 1979 | I44: =VLOOKUP(A44,Ausschreibung!$B$4:$I$35,8,FALSE) -> 2000 m | J44: RC Neptun Neckarelz | L44: =2020-H44 -> 41
A45: 2 | C45: Schönmann Fink | D45: Matthias | E45: =VLOOKUP(A45,Ausschreibung!$B$4:$I$35,4,FALSE) -> Masters A-H, männlich | F45: B | G45: =VLOOKUP(A45,Ausschreibung!$B$4:$I$35,6,FALSE) -> 27 und älter | H45: 1979 | I45: =VLOOKUP(A45,Ausschreibung!$B$4:$I$35,8,FALSE) -> 30 min. | J45: RC Neptun Neckarelz | L45: =2020-H45 -> 41
A46: 25 | C46: Schönmann Fink | D46: Matthias | E46: =VLOOKUP(A46,Ausschreibung!$B$4:$I$35,4,FALSE) -> Masters A-H, männlich | F46: B | G46: =VLOOKUP(A46,Ausschreibung!$B$4:$I$35,6,FALSE) -> 27 und älter | H46: 1979 | I46: =VLOOKUP(A46,Ausschreibung!$B$4:$I$35,8,FALSE) -> 2000 m | J46: RC Neptun Neckarelz | L46: =2020-H46 -> 41
A47: 23 | C47: Bogenschütz | D47: Benjamin | E47: =VLOOKUP(A47,Ausschreibung!$B$4:$I$35,4,FALSE) -> Senioren A | F47: =VLOOKUP(A47,Ausschreibung!$B$4:$I$35,5,FALSE) -> LGW. bis 75 kg | G47: =VLOOKUP(A47,Ausschreibung!$B$4:$I$35,6,FALSE) -> 19 und älter | H47: 1986 | I47: =VLOOKUP(A47,Ausschreibung!$B$4:$I$35,8,FALSE) -> 2000 m | J47: Stuttgarter RG | L47: =2020-H47 -> 34
A48: 28 | C48: Aydin | D48: Semih | E48: =VLOOKUP(A48,Ausschreibung!$B$4:$I$35,4,FALSE) -> Masters A-H, weiblich | F48: A | G48: =VLOOKUP(A48,Ausschreibung!$B$4:$I$35,6,FALSE) -> 27 und älter | H48: 1989 | I48: =VLOOKUP(A48,Ausschreibung!$B$4:$I$35,8,FALSE) -> 1000 m | J48: RC Nürtingen | L48: =2020-H48 -> 31
A49: 25 | C49: Häfner | D49: Christian | E49: =VLOOKUP(A49,Ausschreibung!$B$4:$I$35,4,FALSE) -> Masters A-H, männlich | F49: A | G49: =VLOOKUP(A49,Ausschreibung!$B$4:$I$35,6,FALSE) -> 27 und älter | H49: 1990 | I49: =VLOOKUP(A49,Ausschreibung!$B$4:$I$35,8,FALSE) -> 2000 m | J49: Ruderverein Bad Wimpfen | L49: =2020-H49 -> 30
A50: 16 | C50: Klinge | D50: Jens | E50: =VLOOKUP(A50,Ausschreibung!$B$4:$I$35,4,FALSE) -> Sprint männlich | F50: A | G50: =VLOOKUP(A50,Ausschreibung!$B$4:$I$35,6,FALSE) -> offen | H50: 1990 | I50: =VLOOKUP(A50,Ausschreibung!$B$4:$I$35,8,FALSE) -> 350 m | J50: HRG Schwaben | L50: =2020-H50 -> 30
A51: 24 | C51: Killinger | D51: Cornelius | E51: =VLOOKUP(A51,Ausschreibung!$B$4:$I$35,4,FALSE) -> Senioren A | F51: =VLOOKUP(A51,Ausschreibung!$B$4:$I$35,5,FALSE) -> - | G51: =VLOOKUP(A51,Ausschreibung!$B$4:$I$35,6,FALSE) -> 19 und älter | H51: 1992 | I51: =VLOOKUP(A51,Ausschreibung!$B$4:$I$35,8,FALSE) -> 2000 m | J51: Marbacher Ruderverein | L51: =2020-H51 -> 28
A52: 29 | C52: Killinger | D52: Cornelius/ | E52: =VLOOKUP(A52,Ausschreibung!$B$4:$I$35,4,FALSE) -> Mannschaft offen - 2 Personen | F52: =VLOOKUP(A52,Ausschreibung!$B$4:$I$35,5,FALSE) -> - | G52: =VLOOKUP(A52,Ausschreibung!$B$4:$I$35,6,FALSE) -> offen | H52: 1992 | I52: =VLOOKUP(A52,Ausschreibung!$B$4:$I$35,8,FALSE) -> 5000 m | J52: Marbacher Ruderverein | L52: =2020-H52 -> 28
A53: 16 | C53: Weiß | D53: Fabian | E53: =VLOOKUP(A53,Ausschreibung!$B$4:$I$35,4,FALSE) -> Sprint männlich | F53: A | G53: =VLOOKUP(A53,Ausschreibung!$B$4:$I$35,6,FALSE) -> offen | H53: 1992 | I53: =VLOOKUP(A53,Ausschreibung!$B$4:$I$35,8,FALSE) -> 350 m | J53: HRG Schwaben | L53: =2020-H53 -> 28
A54: 25 | C54: Weiß | D54: Fabian | E54: =VLOOKUP(A54,Ausschreibung!$B$4:$I$35,4,FALSE) -> Masters A-H, männlich | F54: A | G54: =VLOOKUP(A54,Ausschreibung!$B$4:$I$35,6,FALSE) -> 27 und älter | H54: 1992 | I54: =VLOOKUP(A54,Ausschreibung!$B$4:$I$35,8,FALSE) -> 2000 m | J54: HRG Schwaben | L54: =2020-H54 -> 28
A55: 22 | C55: Marquardt | D55: Linda | E55: =VLOOKUP(A55,Ausschreibung!$B$4:$I$35,4,FALSE) -> Seniorinnen A | F55: =VLOOKUP(A55,Ausschreibung!$B$4:$I$35,5,FALSE) -> - | G55: =VLOOKUP(A55,Ausschreibung!$B$4:$I$35,6,FALSE) -> 19 und älter | H55: 1995 | I55: =VLOOKUP(A55,Ausschreibung!$B$4:$I$35,8,FALSE) -> 2000 m | J55: Ruderverein Bad Wimpfen | L55: =2020-H55 -> 25
...

Sheet Rennlisten
B1: 1 | C1: 2 | D1: 3 | E1: 4 | F1: 5 | G1: 6 | H1: 7 | I1: 8 | K1: 9
B2: Rennliste ERGOCUP 2020
B3: Rennen | C3: Wettbewerb | D3: Startzeit | E3: Rennen | F3: Klasse
B4: 1 | C4: =VLOOKUP(B4,Ausschreibung!$B$5:$I$35,2,FALSE) -> Ergocup | D4: =VLOOKUP(B4,Ausschreibung!$B$5:$I$35,3,FALSE) -> 0.375 | E4: Masters A-H, weiblich, 30 Min. | F4: =VLOOKUP(B4,Ausschreibung!$B$5:$I$35,5,FALSE) -> - | G4: =VLOOKUP(B4,Ausschreibung!$B$5:$I$35,6,FALSE) -> 27 und älter | H4: =VLOOKUP(B4,Ausschreibung!$B$5:$I$35,8,FALSE) -> 30 min.
B5: Name | C5: Vorname | D5: Jhg | E5: Klasse | F5: Ergonummer | G5: Ergebnis | H5: Platzierung | I5: Verein
B6: {=IF(ISERROR(INDEX('Eingabe Meldungen'!$C$2:$C$492,LARGE(('Eingabe Meldungen'!$A$2:$A$492=$B$4)*(ROW('Eingabe Meldungen'!$A$2:$A$492)-1),COUNTIF('Eingabe Meldungen'!$A$2:$A$492,$B$4)+1-ROW('Eingabe Meldungen'!A1)))),"",INDEX('Eingabe Meldungen'!$C$2:$C$492,LARGE(('Eingabe Meldungen'!$A$2:$A$492=$B$4)*(ROW('Eingabe Meldungen'!$A$2:$A$492)-1),COUNTIF('Eingabe Meldungen'!$A$2:$A$492,$B$4)+1-ROW('Eingabe Meldungen'!A1))))} -> Reinert | C6: {=IF(ISERROR(INDEX('Eingabe Meldungen'!$D$2:$D$492,LARGE(('Eingabe Meldungen'!$A$2:$A$492=$B$4)*(ROW('Eingabe Meldungen'!$A$2:$A$492)-1),COUNTIF('Eingabe Meldungen'!$A$2:$A$492,$B$4)+1-ROW('Eingabe Meldungen'!A1)))),"",INDEX('Eingabe Meldungen'!$D$2:$D$492,LARGE(('Eingabe Meldungen'!$A$2:$A$492=$B$4)*(ROW('Eingabe Meldungen'!$A$2:$A$492)-1),COUNTIF('Eingabe Meldungen'!$A$2:$A$492,$B$4)+1-ROW('Eingabe Meldungen'!A1))))} -> Ingrid | D6: {=IF(B6<>"",INDEX('Eingabe Meldungen'!$C$2:$H$492,MATCH(B6&C6,'Eingabe Meldungen'!$C$2:$C$492&'Eingabe Meldungen'!$D$2:$D$492,0),6),"")} -> 1960 | E6: {=IF(B6<>"",INDEX('Eingabe Meldungen'!$C$2:$H$492,MATCH(B6&C6,'Eingabe Meldungen'!$C$2:$C$492&'Eingabe Meldungen'!$D$2:$D$492,0),4),"")} -> F | F6: 1 | H6: =RANK(G6,$G$6:$G$18,1) -> #N/A | I6: {=IF(B6<>"",INDEX('Eingabe Meldungen'!$C$2:$J$492,MATCH(B6&C6,'Eingabe Meldungen'!$C$2:$C$492&'Eingabe Meldungen'!$D$2:$D$492,0),8),"")} -> HRG Schwaben
B7: {=IF(ISERROR(INDEX('Eingabe Meldungen'!$C$2:$C$492,LARGE(('Eingabe Meldungen'!$A$2:$A$492=$B$4)*(ROW('Eingabe Meldungen'!$A$2:$A$492)-1),COUNTIF('Eingabe Meldungen'!$A$2:$A$492,$B$4)+1-ROW('Eingabe Meldungen'!A2)))),"",INDEX('Eingabe Meldungen'!$C$2:$C$492,LARGE(('Eingabe Meldungen'!$A$2:$A$492=$B$4)*(ROW('Eingabe Meldungen'!$A$2:$A$492)-1),COUNTIF('Eingabe Meldungen'!$A$2:$A$492,$B$4)+1-ROW('Eingabe Meldungen'!A2))))} -> Schmidt | C7: {=IF(ISERROR(INDEX('Eingabe Meldungen'!$D$2:$D$492,LARGE(('Eingabe Meldungen'!$A$2:$A$492=$B$4)*(ROW('Eingabe Meldungen'!$A$2:$A$492)-1),COUNTIF('Eingabe Meldungen'!$A$2:$A$492,$B$4)+1-ROW('Eingabe Meldungen'!A2)))),"",INDEX('Eingabe Meldungen'!$D$2:$D$492,LARGE(('Eingabe Meldungen'!$A$2:$A$492=$B$4)*(ROW('Eingabe Meldungen'!$A$2:$A$492)-1),COUNTIF('Eingabe Meldungen'!$A$2:$A$492,$B$4)+1-ROW('Eingabe Meldungen'!A2))))} -> Henriette | D7: {=IF(B7<>"",INDEX('Eingabe Meldungen'!$C$2:$H$492,MATCH(B7&C7,'Eingabe Meldungen'!$C$2:$C$492&'Eingabe Meldungen'!$D$2:$D$492,0),6),"")} -> 1965 | E7: E | F7: 2 | H7: =RANK(G7,$G$6:$G$18,1) -> #N/A | I7: {=IF(B7<>"",INDEX('Eingabe Meldungen'!$C$2:$J$492,MATCH(B7&C7,'Eingabe Meldungen'!$C$2:$C$492&'Eingabe Meldungen'!$D$2:$D$492,0),8),"")} -> Marbacher Ruderverein
B8: {=IF(ISERROR(INDEX('Eingabe Meldungen'!$C$2:$C$492,LARGE(('Eingabe Meldungen'!$A$2:$A$492=$B$4)*(ROW('Eingabe Meldungen'!$A$2:$A$492)-1),COUNTIF('Eingabe Meldungen'!$A$2:$A$492,$B$4)+1-ROW('Eingabe Meldungen'!A3)))),"",INDEX('Eingabe Meldungen'!$C$2:$C$492,LARGE(('Eingabe Meldungen'!$A$2:$A$492=$B$4)*(ROW('Eingabe Meldungen'!$A$2:$A$492)-1),COUNTIF('Eingabe Meldungen'!$A$2:$A$492,$B$4)+1-ROW('Eingabe Meldungen'!A3))))} -> Young | C8: {=IF(ISERROR(INDEX('Eingabe Meldungen'!$D$2:$D$492,LARGE(('Eingabe Meldungen'!$A$2:$A$492=$B$4)*(ROW('Eingabe Meldungen'!$A$2:$A$492)-1),COUNTIF('Eingabe Meldungen'!$A$2:$A$492,$B$4)+1-ROW('Eingabe Meldungen'!A3)))),"",INDEX('Eingabe Meldungen'!$D$2:$D$492,LARGE(('Eingabe Meldungen'!$A$2:$A$492=$B$4)*(ROW('Eingabe Meldungen'!$A$2:$A$492)-1),COUNTIF('Eingabe Meldungen'!$A$2:$A$492,$B$4)+1-ROW('Eingabe Meldungen'!A3))))} -> Susan | D8: {=IF(B8<>"",INDEX('Eingabe Meldungen'!$C$2:$H$492,MATCH(B8&C8,'Eingabe Meldungen'!$C$2:$C$492&'Eingabe Meldungen'!$D$2:$D$492,0),6),"")} -> 1965 | E8: E | F8: 3 | H8: =RANK(G8,$G$6:$G$18,1) -> #N/A | I8: {=IF(B8<>"",INDEX('Eingabe Meldungen'!$C$2:$J$492,MATCH(B8&C8,'Eingabe Meldungen'!$C$2:$C$492&'Eingabe Meldungen'!$D$2:$D$492,0),8),"")} -> Sub7 IRC
B9: {=IF(ISERROR(INDEX('Eingabe Meldungen'!$C$2:$C$492,LARGE(('Eingabe Meldungen'!$A$2:$A$492=$B$4)*(ROW('Eingabe Meldungen'!$A$2:$A$492)-1),COUNTIF('Eingabe Meldungen'!$A$2:$A$492,$B$4)+1-ROW('Eingabe Meldungen'!A4)))),"",INDEX('Eingabe Meldungen'!$C$2:$C$492,LARGE(('Eingabe Meldungen'!$A$2:$A$492=$B$4)*(ROW('Eingabe Meldungen'!$A$2:$A$492)-1),COUNTIF('Eingabe Meldungen'!$A$2:$A$492,$B$4)+1-ROW('Eingabe Meldungen'!A4))))} -> Breitenbücher | C9: {=IF(ISERROR(INDEX('Eingabe Meldungen'!$D$2:$D$492,LARGE(('Eingabe Meldungen'!$A$2:$A$492=$B$4)*(ROW('Eingabe Meldungen'!$A$2:$A$492)-1),COUNTIF('Eingabe Meldungen'!$A$2:$A$492,$B$4)+1-ROW('Eingabe Meldungen'!A4)))),"",INDEX('Eingabe Meldungen'!$D$2:$D$492,LARGE(('Eingabe Meldungen'!$A$2:$A$492=$B$4)*(ROW('Eingabe Meldungen'!$A$2:$A$492)-1),COUNTIF('Eingabe Meldungen'!$A$2:$A$492,$B$4)+1-ROW('Eingabe Meldungen'!A4))))} -> Heike | D9: {=IF(B9<>"",INDEX('Eingabe Meldungen'!$C$2:$H$492,MATCH(B9&C9,'Eingabe Meldungen'!$C$2:$C$492&'Eingabe Meldungen'!$D$2:$D$492,0),6),"")} -> 1967 | E9: {=IF(B9<>"",INDEX('Eingabe Meldungen'!$C$2:$H$492,MATCH(B9&C9,'Eingabe Meldungen'!$C$2:$C$492&'Eingabe Meldungen'!$D$2:$D$492,0),4),"")} -> D | F9: 4 | H9: =RANK(G9,$G$6:$G$18,1) -> #N/A | I9: {=IF(B9<>"",INDEX('Eingabe Meldungen'!$C$2:$J$492,MATCH(B9&C9,'Eingabe Meldungen'!$C$2:$C$492&'Eingabe Meldungen'!$D$2:$D$492,0),8),"")} -> Marbacher Ruderverein
B10: {=IF(ISERROR(INDEX('Eingabe Meldungen'!$C$2:$C$492,LARGE(('Eingabe Meldungen'!$A$2:$A$492=$B$4)*(ROW('Eingabe Meldungen'!$A$2:$A$492)-1),COUNTIF('Eingabe Meldungen'!$A$2:$A$492,$B$4)+1-ROW('Eingabe Meldungen'!A5)))),"",INDEX('Eingabe Meldungen'!$C$2:$C$492,LARGE(('Eingabe Meldungen'!$A$2:$A$492=$B$4)*(ROW('Eingabe Meldungen'!$A$2:$A$492)-1),COUNTIF('Eingabe Meldungen'!$A$2:$A$492,$B$4)+1-ROW('Eingabe Meldungen'!A5))))} -> Schmidt | C10: {=IF(ISERROR(INDEX('Eingabe Meldungen'!$D$2:$D$492,LARGE(('Eingabe Meldungen'!$A$2:$A$492=$B$4)*(ROW('Eingabe Meldungen'!$A$2:$A$492)-1),COUNTIF('Eingabe Meldungen'!$A$2:$A$492,$B$4)+1-ROW('Eingabe Meldungen'!A5)))),"",INDEX('Eingabe Meldungen'!$D$2:$D$492,LARGE(('Eingabe Meldungen'!$A$2:$A$492=$B$4)*(ROW('Eingabe Meldungen'!$A$2:$A$492)-1),COUNTIF('Eingabe Meldungen'!$A$2:$A$492,$B$4)+1-ROW('Eingabe Meldungen'!A5))))} -> Uta | D10: {=IF(B10<>"",INDEX('Eingabe Meldungen'!$C$2:$H$492,MATCH(B10&C10,'Eingabe Meldungen'!$C$2:$C$492&'Eingabe Meldungen'!$D$2:$D$492,0),6),"")} -> 1972 | E10: {=IF(B10<>"",INDEX('Eingabe Meldungen'!$C$2:$H$492,MATCH(B10&C10,'Eingabe Meldungen'!$C$2:$C$492&'Eingabe Meldungen'!$D$2:$D$492,0),4),"")} -> C | F10: 5 | H10: =RANK(G10,$G$6:$G$18,1) -> #N/A | I10: {=IF(B10<>"",INDEX('Eingabe Meldungen'!$C$2:$J$492,MATCH(B10&C10,'Eingabe Meldungen'!$C$2:$C$492&'Eingabe Meldungen'!$D$2:$D$492,0),8),"")} -> Marbacher Ruderverein
B11: {=IF(ISERROR(INDEX('Eingabe Meldungen'!$C$2:$C$492,LARGE(('Eingabe Meldungen'!$A$2:$A$492=$B$4)*(ROW('Eingabe Meldungen'!$A$2:$A$492)-1),COUNTIF('Eingabe Meldungen'!$A$2:$A$492,$B$4)+1-ROW('Eingabe Meldungen'!A6)))),"",INDEX('Eingabe Meldungen'!$C$2:$C$492,LARGE(('Eingabe Meldungen'!$A$2:$A$492=$B$4)*(ROW('Eingabe Meldungen'!$A$2:$A$492)-1),COUNTIF('Eingabe Meldungen'!$A$2:$A$492,$B$4)+1-ROW('Eingabe Meldungen'!A6))))} -> Vogt | C11: {=IF(ISERROR(INDEX('Eingabe Meldungen'!$D$2:$D$492,LARGE(('Eingabe Meldungen'!$A$2:$A$492=$B$4)*(ROW('Eingabe Meldungen'!$A$2:$A$492)-1),COUNTIF('Eingabe Meldungen'!$A$2:$A$492,$B$4)+1-ROW('Eingabe Meldungen'!A6)))),"",INDEX('Eingabe Meldungen'!$D$2:$D$492,LARGE(('Eingabe Meldungen'!$A$2:$A$492=$B$4)*(ROW('Eingabe Meldungen'!$A$2:$A$492)-1),COUNTIF('Eingabe Meldungen'!$A$2:$A$492,$B$4)+1-ROW('Eingabe Meldungen'!A6))))} -> Antje | D11: {=IF(B11<>"",INDEX('Eingabe Meldungen'!$C$2:$H$492,MATCH(B11&C11,'Eingabe Meldungen'!$C$2:$C$492&'Eingabe Meldungen'!$D$2:$D$492,0),6),"")} -> 1975 | E11: {=IF(B11<>"",INDEX('Eingabe Meldungen'!$C$2:$H$492,MATCH(B11&C11,'Eingabe Meldungen'!$C$2:$C$492&'Eingabe Meldungen'!$D$2:$D$492,0),4),"")} -> C | F11: 6 | H11: =RANK(G11,$G$6:$G$18,1) -> #N/A | I11: {=IF(B11<>"",INDEX('Eingabe Meldungen'!$C$2:$J$492,MATCH(B11&C11,'Eingabe Meldungen'!$C$2:$C$492&'Eingabe Meldungen'!$D$2:$D$492,0),8),"")} -> HRG Schwaben
B12: {=IF(ISERROR(INDEX('Eingabe Meldungen'!$C$2:$C$492,LARGE(('Eingabe Meldungen'!$A$2:$A$492=$B$4)*(ROW('Eingabe Meldungen'!$A$2:$A$492)-1),COUNTIF('Eingabe Meldungen'!$A$2:$A$492,$B$4)+1-ROW('Eingabe Meldungen'!A7)))),"",INDEX('Eingabe Meldungen'!$C$2:$C$492,LARGE(('Eingabe Meldungen'!$A$2:$A$492=$B$4)*(ROW('Eingabe Meldungen'!$A$2:$A$492)-1),COUNTIF('Eingabe Meldungen'!$A$2:$A$492,$B$4)+1-ROW('Eingabe Meldungen'!A7))))} -> Munke | C12: {=IF(ISERROR(INDEX('Eingabe Meldungen'!$D$2:$D$492,LARGE(('Eingabe Meldungen'!$A$2:$A$492=$B$4)*(ROW('Eingabe Meldungen'!$A$2:$A$492)-1),COUNTIF('Eingabe Meldungen'!$A$2:$A$492,$B$4)+1-ROW('Eingabe Meldungen'!A7)))),"",INDEX('Eingabe Meldungen'!$D$2:$D$492,LARGE(('Eingabe Meldungen'!$A$2:$A$492=$B$4)*(ROW('Eingabe Meldungen'!$A$2:$A$492)-1),COUNTIF('Eingabe Meldungen'!$A$2:$A$492,$B$4)+1-ROW('Eingabe Meldungen'!A7))))} -> Steffi | D12: {=IF(B12<>"",INDEX('Eingabe Meldungen'!$C$2:$H$492,MATCH(B12&C12,'Eingabe Meldungen'!$C$2:$C$492&'Eingabe Meldungen'!$D$2:$D$492,0),6),"")} -> 1968 | E12: {=IF(B12<>"",INDEX('Eingabe Meldungen'!$C$2:$H$492,MATCH(B12&C12,'Eingabe Meldungen'!$C$2:$C$492&'Eingabe Meldungen'!$D$2:$D$492,0),4),"")} -> D | F12: 7 | H12: =RANK(G12,$G$6:$G$18,1) -> #N/A | I12: {=IF(B12<>"",INDEX('Eingabe Meldungen'!$C$2:$J$492,MATCH(B12&C12,'Eingabe Meldungen'!$C$2:$C$492&'Eingabe Meldungen'!$D$2:$D$492,0),8),"")} -> WSV Schifferclub Neckarrems
B13: {=IF(ISERROR(INDEX('Eingabe Meldungen'!$C$2:$C$492,LARGE(('Eingabe Meldungen'!$A$2:$A$492=$B$4)*(ROW('Eingabe Meldungen'!$A$2:$A$492)-1),COUNTIF('Eingabe Meldungen'!$A$2:$A$492,$B$4)+1-ROW('Eingabe Meldungen'!A8)))),"",INDEX('Eingabe Meldungen'!$C$2:$C$492,LARGE(('Eingabe Meldungen'!$A$2:$A$492=$B$4)*(ROW('Eingabe Meldungen'!$A$2:$A$492)-1),COUNTIF('Eingabe Meldungen'!$A$2:$A$492,$B$4)+1-ROW('Eingabe Meldungen'!A8))))} -> Wöppel | C13: {=IF(ISERROR(INDEX('Eingabe Meldungen'!$D$2:$D$492,LARGE(('Eingabe Meldungen'!$A$2:$A$492=$B$4)*(ROW('Eingabe Meldungen'!$A$2:$A$492)-1),COUNTIF('Eingabe Meldungen'!$A$2:$A$492,$B$4)+1-ROW('Eingabe Meldungen'!A8)))),"",INDEX('Eingabe Meldungen'!$D$2:$D$492,LARGE(('Eingabe Meldungen'!$A$2:$A$492=$B$4)*(ROW('Eingabe Meldungen'!$A$2:$A$492)-1),COUNTIF('Eingabe Meldungen'!$A$2:$A$492,$B$4)+1-ROW('Eingabe Meldungen'!A8))))} -> Stefanie | D13: {=IF(B13<>"",INDEX('Eingabe Meldungen'!$C$2:$H$492,MATCH(B13&C13,'Eingabe Meldungen'!$C$2:$C$492&'Eingabe Meldungen'!$D$2:$D$492,0),6),"")} -> 1971 | E13: {=IF(B13<>"",INDEX('Eingabe Meldungen'!$C$2:$H$492,MATCH(B13&C13,'Eingabe Meldungen'!$C$2:$C$492&'Eingabe Meldungen'!$D$2:$D$492,0),4),"")} -> C | F13: 8 | H13: =RANK(G13,$G$6:$G$18,1) -> #N/A | I13: {=IF(B13<>"",INDEX('Eingabe Meldungen'!$C$2:$J$492,MATCH(B13&C13,'Eingabe Meldungen'!$C$2:$C$492&'Eingabe Meldungen'!$D$2:$D$492,0),8),"")} -> WSV Schifferclub Neckarrems
B14: {=IF(ISERROR(INDEX('Eingabe Meldungen'!$C$2:$C$492,LARGE(('Eingabe Meldungen'!$A$2:$A$492=$B$4)*(ROW('Eingabe Meldungen'!$A$2:$A$492)-1),COUNTIF('Eingabe Meldungen'!$A$2:$A$492,$B$4)+1-ROW('Eingabe Meldungen'!A9)))),"",INDEX('Eingabe Meldungen'!$C$2:$C$492,LARGE(('Eingabe Meldungen'!$A$2:$A$492=$B$4)*(ROW('Eingabe Meldungen'!$A$2:$A$492)-1),COUNTIF('Eingabe Meldungen'!$A$2:$A$492,$B$4)+1-ROW('Eingabe Meldungen'!A9))))} | C14: {=IF(ISERROR(INDEX('Eingabe Meldungen'!$D$2:$D$492,LARGE(('Eingabe Meldungen'!$A$2:$A$492=$B$4)*(ROW('Eingabe Meldungen'!$A$2:$A$492)-1),COUNTIF('Eingabe Meldungen'!$A$2:$A$492,$B$4)+1-ROW('Eingabe Meldungen'!A9)))),"",INDEX('Eingabe Meldungen'!$D$2:$D$492,LARGE(('Eingabe Meldungen'!$A$2:$A$492=$B$4)*(ROW('Eingabe Meldungen'!$A$2:$A$492)-1),COUNTIF('Eingabe Meldungen'!$A$2:$A$492,$B$4)+1-ROW('Eingabe Meldungen'!A9))))} | D14: {=IF(B14<>"",INDEX('Eingabe Meldungen'!$C$2:$H$492,MATCH(B14&C14,'Eingabe Meldungen'!$C$2:$C$492&'Eingabe Meldungen'!$D$2:$D$492,0),6),"")} | E14: {=IF(B14<>"",INDEX('Eingabe Meldungen'!$C$2:$H$492,MATCH(B14&C14,'Eingabe Meldungen'!$C$2:$C$492&'Eingabe Meldungen'!$D$2:$D$492,0),4),"")} | F14: 9 | H14: =RANK(G14,$G$6:$G$18,1) -> #N/A | I14: {=IF(B14<>"",INDEX('Eingabe Meldungen'!$C$2:$J$492,MATCH(B14&C14,'Eingabe Meldungen'!$C$2:$C$492&'Eingabe Meldungen'!$D$2:$D$492,0),8),"")}
B15: {=IF(ISERROR(INDEX('Eingabe Meldungen'!$C$2:$C$492,LARGE(('Eingabe Meldungen'!$A$2:$A$492=$B$4)*(ROW('Eingabe Meldungen'!$A$2:$A$492)-1),COUNTIF('Eingabe Meldungen'!$A$2:$A$492,$B$4)+1-ROW('Eingabe Meldungen'!A10)))),"",INDEX('Eingabe Meldungen'!$C$2:$C$492,LARGE(('Eingabe Meldungen'!$A$2:$A$492=$B$4)*(ROW('Eingabe Meldungen'!$A$2:$A$492)-1),COUNTIF('Eingabe Meldungen'!$A$2:$A$492,$B$4)+1-ROW('Eingabe Meldungen'!A10))))} | C15: {=IF(ISERROR(INDEX('Eingabe Meldungen'!$D$2:$D$492,LARGE(('Eingabe Meldungen'!$A$2:$A$492=$B$4)*(ROW('Eingabe Meldungen'!$A$2:$A$492)-1),COUNTIF('Eingabe Meldungen'!$A$2:$A$492,$B$4)+1-ROW('Eingabe Meldungen'!A10)))),"",INDEX('Eingabe Meldungen'!$D$2:$D$492,LARGE(('Eingabe Meldungen'!$A$2:$A$492=$B$4)*(ROW('Eingabe Meldungen'!$A$2:$A$492)-1),COUNTIF('Eingabe Meldungen'!$A$2:$A$492,$B$4)+1-ROW('Eingabe Meldungen'!A10))))} | D15: {=IF(B15<>"",INDEX('Eingabe Meldungen'!$C$2:$H$492,MATCH(B15&C15,'Eingabe Meldungen'!$C$2:$C$492&'Eingabe Meldungen'!$D$2:$D$492,0),6),"")} | E15: {=IF(B15<>"",INDEX('Eingabe Meldungen'!$C$2:$H$492,MATCH(B15&C15,'Eingabe Meldungen'!$C$2:$C$492&'Eingabe Meldungen'!$D$2:$D$492,0),4),"")} | F15: 10 | H15: =RANK(G15,$G$6:$G$18,1) -> #N/A | I15: {=IF(B15<>"",INDEX('Eingabe Meldungen'!$C$2:$J$492,MATCH(B15&C15,'Eingabe Meldungen'!$C$2:$C$492&'Eingabe Meldungen'!$D$2:$D$492,0),8),"")}
B16: {=IF(ISERROR(INDEX('Eingabe Meldungen'!$C$2:$C$492,LARGE(('Eingabe Meldungen'!$A$2:$A$492=$B$4)*(ROW('Eingabe Meldungen'!$A$2:$A$492)-1),COUNTIF('Eingabe Meldungen'!$A$2:$A$492,$B$4)+1-ROW('Eingabe Meldungen'!A11)))),"",INDEX('Eingabe Meldungen'!$C$2:$C$492,LARGE(('Eingabe Meldungen'!$A$2:$A$492=$B$4)*(ROW('Eingabe Meldungen'!$A$2:$A$492)-1),COUNTIF('Eingabe Meldungen'!$A$2:$A$492,$B$4)+1-ROW('Eingabe Meldungen'!A11))))} | C16: {=IF(ISERROR(INDEX('Eingabe Meldungen'!$D$2:$D$492,LARGE(('Eingabe Meldungen'!$A$2:$A$492=$B$4)*(ROW('Eingabe Meldungen'!$A$2:$A$492)-1),COUNTIF('Eingabe Meldungen'!$A$2:$A$492,$B$4)+1-ROW('Eingabe Meldungen'!A11)))),"",INDEX('Eingabe Meldungen'!$D$2:$D$492,LARGE(('Eingabe Meldungen'!$A$2:$A$492=$B$4)*(ROW('Eingabe Meldungen'!$A$2:$A$492)-1),COUNTIF('Eingabe Meldungen'!$A$2:$A$492,$B$4)+1-ROW('Eingabe Meldungen'!A11))))} | D16: {=IF(B16<>"",INDEX('Eingabe Meldungen'!$C$2:$H$492,MATCH(B16&C16,'Eingabe Meldungen'!$C$2:$C$492&'Eingabe Meldungen'!$D$2:$D$492,0),6),"")} | E16: {=IF(B16<>"",INDEX('Eingabe Meldungen'!$C$2:$H$492,MATCH(B16&C16,'Eingabe Meldungen'!$C$2:$C$492&'Eingabe Meldungen'!$D$2:$D$492,0),4),"")} | F16: 11 | H16: =RANK(G16,$G$6:$G$18,1) -> #N/A | I16: {=IF(B16<>"",INDEX('Eingabe Meldungen'!$C$2:$J$492,MATCH(B16&C16,'Eingabe Meldungen'!$C$2:$C$492&'Eingabe Meldungen'!$D$2:$D$492,0),8),"")}
B17: {=IF(ISERROR(INDEX('Eingabe Meldungen'!$C$2:$C$492,LARGE(('Eingabe Meldungen'!$A$2:$A$492=$B$4)*(ROW('Eingabe Meldungen'!$A$2:$A$492)-1),COUNTIF('Eingabe Meldungen'!$A$2:$A$492,$B$4)+1-ROW('Eingabe Meldungen'!A12)))),"",INDEX('Eingabe Meldungen'!$C$2:$C$492,LARGE(('Eingabe Meldungen'!$A$2:$A$492=$B$4)*(ROW('Eingabe Meldungen'!$A$2:$A$492)-1),COUNTIF('Eingabe Meldungen'!$A$2:$A$492,$B$4)+1-ROW('Eingabe Meldungen'!A12))))} | C17: {=IF(ISERROR(INDEX('Eingabe Meldungen'!$D$2:$D$492,LARGE(('Eingabe Meldungen'!$A$2:$A$492=$B$4)*(ROW('Eingabe Meldungen'!$A$2:$A$492)-1),COUNTIF('Eingabe Meldungen'!$A$2:$A$492,$B$4)+1-ROW('Eingabe Meldungen'!A12)))),"",INDEX('Eingabe Meldungen'!$D$2:$D$492,LARGE(('Eingabe Meldungen'!$A$2:$A$492=$B$4)*(ROW('Eingabe Meldungen'!$A$2:$A$492)-1),COUNTIF('Eingabe Meldungen'!$A$2:$A$492,$B$4)+1-ROW('Eingabe Meldungen'!A12))))} | D17: {=IF(B17<>"",INDEX('Eingabe Meldungen'!$C$2:$H$492,MATCH(B17&C17,'Eingabe Meldungen'!$C$2:$C$492&'Eingabe Meldungen'!$D$2:$D$492,0),6),"")} | E17: {=IF(B17<>"",INDEX('Eingabe Meldungen'!$C$2:$H$492,MATCH(B17&C17,'Eingabe Meldungen'!$C$2:$C$492&'Eingabe Meldungen'!$D$2:$D$492,0),4),"")} | F17: 12 | H17: =RANK(G17,$G$6:$G$18,1) -> #N/A | I17: {=IF(B17<>"",INDEX('Eingabe Meldungen'!$C$2:$J$492,MATCH(B17&C17,'Eingabe Meldungen'!$C$2:$C$492&'Eingabe Meldungen'!$D$2:$D$492,0),8),"")}
B18: {=IF(ISERROR(INDEX('Eingabe Meldungen'!$C$2:$C$492,LARGE(('Eingabe Meldungen'!$A$2:$A$492=$B$4)*(ROW('Eingabe Meldungen'!$A$2:$A$492)-1),COUNTIF('Eingabe Meldungen'!$A$2:$A$492,$B$4)+1-ROW('Eingabe Meldungen'!A13)))),"",INDEX('Eingabe Meldungen'!$C$2:$C$492,LARGE(('Eingabe Meldungen'!$A$2:$A$492=$B$4)*(ROW('Eingabe Meldungen'!$A$2:$A$492)-1),COUNTIF('Eingabe Meldungen'!$A$2:$A$492,$B$4)+1-ROW('Eingabe Meldungen'!A13))))} | C18: {=IF(ISERROR(INDEX('Eingabe Meldungen'!$D$2:$D$492,LARGE(('Eingabe Meldungen'!$A$2:$A$492=$B$4)*(ROW('Eingabe Meldungen'!$A$2:$A$492)-1),COUNTIF('Eingabe Meldungen'!$A$2:$A$492,$B$4)+1-ROW('Eingabe Meldungen'!A13)))),"",INDEX('Eingabe Meldungen'!$D$2:$D$492,LARGE(('Eingabe Meldungen'!$A$2:$A$492=$B$4)*(ROW('Eingabe Meldungen'!$A$2:$A$492)-1),COUNTIF('Eingabe Meldungen'!$A$2:$A$492,$B$4)+1-ROW('Eingabe Meldungen'!A13))))} | D18: {=IF(B18<>"",INDEX('Eingabe Meldungen'!$C$2:$H$492,MATCH(B18&C18,'Eingabe Meldungen'!$C$2:$C$492&'Eingabe Meldungen'!$D$2:$D$492,0),6),"")} | E18: {=IF(B18<>"",INDEX('Eingabe Meldungen'!$C$2:$H$492,MATCH(B18&C18,'Eingabe Meldungen'!$C$2:$C$492&'Eingabe Meldungen'!$D$2:$D$492,0),4),"")} | F18: 13 | H18: =RANK(G18,$G$6:$G$18,1) -> #N/A | I18: {=IF(B18<>"",INDEX('Eingabe Meldungen'!$C$2:$J$492,MATCH(B18&C18,'Eingabe Meldungen'!$C$2:$C$492&'Eingabe Meldungen'!$D$2:$D$492,0),8),"")}
B20: =B4+1 -> 2 | C20: =VLOOKUP(B20,Ausschreibung!$B$5:$I$35,2,FALSE) -> Ergocup | D20: A1 09:40 A2 10:20 A3 11:00 | E20: Masters A-H, männlich, 30 Min. | F20: =VLOOKUP(B20,Ausschreibung!$B$5:$I$35,5,FALSE) -> - | G20: =VLOOKUP(B20,Ausschreibung!$B$5:$I$35,6,FALSE) -> 27 und älter | H20: =VLOOKUP(B20,Ausschreibung!$B$5:$I$35,8,FALSE) -> 30 min.
B21: Name | C21: Vorname | D21: Jhg | E21: Klasse | F21: Ergonummer | G21: Ergebnis | H21: Platzierung | I21: Verein
B22: {=IF(ISERROR(INDEX('Eingabe Meldungen'!$C$2:$C$492,LARGE(('Eingabe Meldungen'!$A$2:$A$492=$B$20)*(ROW('Eingabe Meldungen'!$A$2:$A$492)-1),COUNTIF('Eingabe Meldungen'!$A$2:$A$492,$B$20)+1-ROW('Eingabe Meldungen'!A1)))),"",INDEX('Eingabe Meldungen'!$C$2:$C$492,LARGE(('Eingabe Meldungen'!$A$2:$A$492=$B$20)*(ROW('Eingabe Meldungen'!$A$2:$A$492)-1),COUNTIF('Eingabe Meldungen'!$A$2:$A$492,$B$20)+1-ROW('Eingabe Meldungen'!A1))))} -> Gocke | C22: {=IF(ISERROR(INDEX('Eingabe Meldungen'!$D$2:$D$492,LARGE(('Eingabe Meldungen'!$A$2:$A$492=$B$20)*(ROW('Eingabe Meldungen'!$A$2:$A$492)-1),COUNTIF('Eingabe Meldungen'!$A$2:$A$492,$B$20)+1-ROW('Eingabe Meldungen'!A1)))),"",INDEX('Eingabe Meldungen'!$D$2:$D$492,LARGE(('Eingabe Meldungen'!$A$2:$A$492=$B$20)*(ROW('Eingabe Meldungen'!$A$2:$A$492)-1),COUNTIF('Eingabe Meldungen'!$A$2:$A$492,$B$20)+1-ROW('Eingabe Meldungen'!A1))))} -> Eberhard | D22: {=IF(B22<>"",INDEX('Eingabe Meldungen'!$C$2:$H$492,MATCH(B22&C22,'Eingabe Meldungen'!$C$2:$C$492&'Eingabe Meldungen'!$D$2:$D$492,0),6),"")} -> 1940 | E22: {=IF(B22<>"",INDEX('Eingabe Meldungen'!$C$2:$H$492,MATCH(B22&C22,'Eingabe Meldungen'!$C$2:$C$492&'Eingabe Meldungen'!$D$2:$D$492,0),4),"")} -> J | F22: 1 | H22: =RANK(G22,$G$22:$G$51,1) -> #N/A | I22: {=IF(B22<>"",INDEX('Eingabe Meldungen'!$C$2:$J$492,MATCH(B22&C22,'Eingabe Meldungen'!$C$2:$C$492&'Eingabe Meldungen'!$D$2:$D$492,0),8),"")} -> RC Neptun Neckarelz | K22: A1
B23: {=IF(ISERROR(INDEX('Eingabe Meldungen'!$C$2:$C$492,LARGE(('Eingabe Meldungen'!$A$2:$A$492=$B$20)*(ROW('Eingabe Meldungen'!$A$2:$A$492)-1),COUNTIF('Eingabe Meldungen'!$A$2:$A$492,$B$20)+1-ROW('Eingabe Meldungen'!A2)))),"",INDEX('Eingabe Meldungen'!$C$2:$C$492,LARGE(('Eingabe Meldungen'!$A$2:$A$492=$B$20)*(ROW('Eingabe Meldungen'!$A$2:$A$492)-1),COUNTIF('Eingabe Meldungen'!$A$2:$A$492,$B$20)+1-ROW('Eingabe Meldungen'!A2))))} -> Schultheiß | C23: {=IF(ISERROR(INDEX('Eingabe Meldungen'!$D$2:$D$492,LARGE(('Eingabe Meldungen'!$A$2:$A$492=$B$20)*(ROW('Eingabe Meldungen'!$A$2:$A$492)-1),COUNTIF('Eingabe Meldungen'!$A$2:$A$492,$B$20)+1-ROW('Eingabe Meldungen'!A2)))),"",INDEX('Eingabe Meldungen'!$D$2:$D$492,LARGE(('Eingabe Meldungen'!$A$2:$A$492=$B$20)*(ROW('Eingabe Meldungen'!$A$2:$A$492)-1),COUNTIF('Eingabe Meldungen'!$A$2:$A$492,$B$20)+1-ROW('Eingabe Meldungen'!A2))))} -> Günther | D23: {=IF(B23<>"",INDEX('Eingabe Meldungen'!$C$2:$H$492,MATCH(B23&C23,'Eingabe Meldungen'!$C$2:$C$492&'Eingabe Meldungen'!$D$2:$D$492,0),6),"")} -> 1942 | E23: I | F23: 2 | H23: =RANK(G23,$G$22:$G$51,1) -> #N/A | I23: {=IF(B23<>"",INDEX('Eingabe Meldungen'!$C$2:$J$492,MATCH(B23&C23,'Eingabe Meldungen'!$C$2:$C$492&'Eingabe Meldungen'!$D$2:$D$492,0),8),"")} -> RC Neptun Neckarelz
B24: {=IF(ISERROR(INDEX('Eingabe Meldungen'!$C$2:$C$492,LARGE(('Eingabe Meldungen'!$A$2:$A$492=$B$20)*(ROW('Eingabe Meldungen'!$A$2:$A$492)-1),COUNTIF('Eingabe Meldungen'!$A$2:$A$492,$B$20)+1-ROW('Eingabe Meldungen'!A3)))),"",INDEX('Eingabe Meldungen'!$C$2:$C$492,LARGE(('Eingabe Meldungen'!$A$2:$A$492=$B$20)*(ROW('Eingabe Meldungen'!$A$2:$A$492)-1),COUNTIF('Eingabe Meldungen'!$A$2:$A$492,$B$20)+1-ROW('Eingabe Meldungen'!A3))))} -> Diem | C24: {=IF(ISERROR(INDEX('Eingabe Meldungen'!$D$2:$D$492,LARGE(('Eingabe Meldungen'!$A$2:$A$492=$B$20)*(ROW('Eingabe Meldungen'!$A$2:$A$492)-1),COUNTIF('Eingabe Meldungen'!$A$2:$A$492,$B$20)+1-ROW('Eingabe Meldungen'!A3)))),"",INDEX('Eingabe Meldungen'!$D$2:$D$492,LARGE(('Eingabe Meldungen'!$A$2:$A$492=$B$20)*(ROW('Eingabe Meldungen'!$A$2:$A$492)-1),COUNTIF('Eingabe Meldungen'!$A$2:$A$492,$B$20)+1-ROW('Eingabe Meldungen'!A3))))} -> Werner | D24: {=IF(B24<>"",INDEX('Eingabe Meldungen'!$C$2:$H$492,MATCH(B24&C24,'Eingabe Meldungen'!$C$2:$C$492&'Eingabe Meldungen'!$D$2:$D$492,0),6),"")} -> 1943 | E24: J | F24: 3 | H24: =RANK(G24,$G$22:$G$51,1) -> #N/A | I24: {=IF(B24<>"",INDEX('Eingabe Meldungen'!$C$2:$J$492,MATCH(B24&C24,'Eingabe Meldungen'!$C$2:$C$492&'Eingabe Meldungen'!$D$2:$D$492,0),8),"")} -> RC Neptun Neckarelz
B25: {=IF(ISERROR(INDEX('Eingabe Meldungen'!$C$2:$C$492,LARGE(('Eingabe Meldungen'!$A$2:$A$492=$B$20)*(ROW('Eingabe Meldungen'!$A$2:$A$492)-1),COUNTIF('Eingabe Meldungen'!$A$2:$A$492,$B$20)+1-ROW('Eingabe Meldungen'!A4)))),"",INDEX('Eingabe Meldungen'!$C$2:$C$492,LARGE(('Eingabe Meldungen'!$A$2:$A$492=$B$20)*(ROW('Eingabe Meldungen'!$A$2:$A$492)-1),COUNTIF('Eingabe Meldungen'!$A$2:$A$492,$B$20)+1-ROW('Eingabe Meldungen'!A4))))} -> Schmiedeknecht | C25: {=IF(ISERROR(INDEX('Eingabe Meldungen'!$D$2:$D$492,LARGE(('Eingabe Meldungen'!$A$2:$A$492=$B$20)*(ROW('Eingabe Meldungen'!$A$2:$A$492)-1),COUNTIF('Eingabe Meldungen'!$A$2:$A$492,$B$20)+1-ROW('Eingabe Meldungen'!A4)))),"",INDEX('Eingabe Meldungen'!$D$2:$D$492,LARGE(('Eingabe Meldungen'!$A$2:$A$492=$B$20)*(ROW('Eingabe Meldungen'!$A$2:$A$492)-1),COUNTIF('Eingabe Meldungen'!$A$2:$A$492,$B$20)+1-ROW('Eingabe Meldungen'!A4))))} -> Helmut | D25: {=IF(B25<>"",INDEX('Eingabe Meldungen'!$C$2:$H$492,MATCH(B25&C25,'Eingabe Meldungen'!$C$2:$C$492&'Eingabe Meldungen'!$D$2:$D$492,0),6),"")} -> 1947 | E25: {=IF(B25<>"",INDEX('Eingabe Meldungen'!$C$2:$H$492,MATCH(B25&C25,'Eingabe Meldungen'!$C$2:$C$492&'Eingabe Meldungen'!$D$2:$D$492,0),4),"")} -> H | F25: 4 | H25: =RANK(G25,$G$22:$G$51,1) -> #N/A | I25: {=IF(B25<>"",INDEX('Eingabe Meldungen'!$C$2:$J$492,MATCH(B25&C25,'Eingabe Meldungen'!$C$2:$C$492&'Eingabe Meldungen'!$D$2:$D$492,0),8),"")} -> Ruderverein Bad Wimpfen
B26: {=IF(ISERROR(INDEX('Eingabe Meldungen'!$C$2:$C$492,LARGE(('Eingabe Meldungen'!$A$2:$A$492=$B$20)*(ROW('Eingabe Meldungen'!$A$2:$A$492)-1),COUNTIF('Eingabe Meldungen'!$A$2:$A$492,$B$20)+1-ROW('Eingabe Meldungen'!A5)))),"",INDEX('Eingabe Meldungen'!$C$2:$C$492,LARGE(('Eingabe Meldungen'!$A$2:$A$492=$B$20)*(ROW('Eingabe Meldungen'!$A$2:$A$492)-1),COUNTIF('Eingabe Meldungen'!$A$2:$A$492,$B$20)+1-ROW('Eingabe Meldungen'!A5))))} -> Vollmer | C26: {=IF(ISERROR(INDEX('Eingabe Meldungen'!$D$2:$D$492,LARGE(('Eingabe Meldungen'!$A$2:$A$492=$B$20)*(ROW('Eingabe Meldungen'!$A$2:$A$492)-1),COUNTIF('Eingabe Meldungen'!$A$2:$A$492,$B$20)+1-ROW('Eingabe Meldungen'!A5)))),"",INDEX('Eingabe Meldungen'!$D$2:$D$492,LARGE(('Eingabe Meldungen'!$A$2:$A$492=$B$20)*(ROW('Eingabe Meldungen'!$A$2:$A$492)-1),COUNTIF('Eingabe Meldungen'!$A$2:$A$492,$B$20)+1-ROW('Eingabe Meldungen'!A5))))} -> Gerhard | D26: {=IF(B26<>"",INDEX('Eingabe Meldungen'!$C$2:$H$492,MATCH(B26&C26,'Eingabe Meldungen'!$C$2:$C$492&'Eingabe Meldungen'!$D$2:$D$492,0),6),"")} -> 1948 | E26: {=IF(B26<>"",INDEX('Eingabe Meldungen'!$C$2:$H$492,MATCH(B26&C26,'Eingabe Meldungen'!$C$2:$C$492&'Eingabe Meldungen'!$D$2:$D$492,0),4),"")} -> H | F26: 5 | H26: =RANK(G26,$G$22:$G$51,1) -> #N/A | I26: {=IF(B26<>"",INDEX('Eingabe Meldungen'!$C$2:$J$492,MATCH(B26&C26,'Eingabe Meldungen'!$C$2:$C$492&'Eingabe Meldungen'!$D$2:$D$492,0),8),"")} -> HRG Schwaben
B27: {=IF(ISERROR(INDEX('Eingabe Meldungen'!$C$2:$C$492,LARGE(('Eingabe Meldungen'!$A$2:$A$492=$B$20)*(ROW('Eingabe Meldungen'!$A$2:$A$492)-1),COUNTIF('Eingabe Meldungen'!$A$2:$A$492,$B$20)+1-ROW('Eingabe Meldungen'!A6)))),"",INDEX('Eingabe Meldungen'!$C$2:$C$492,LARGE(('Eingabe Meldungen'!$A$2:$A$492=$B$20)*(ROW('Eingabe Meldungen'!$A$2:$A$492)-1),COUNTIF('Eingabe Meldungen'!$A$2:$A$492,$B$20)+1-ROW('Eingabe Meldungen'!A6))))} -> Schmidt | C27: {=IF(ISERROR(INDEX('Eingabe Meldungen'!$D$2:$D$492,LARGE(('Eingabe Meldungen'!$A$2:$A$492=$B$20)*(ROW('Eingabe Meldungen'!$A$2:$A$492)-1),COUNTIF('Eingabe Meldungen'!$A$2:$A$492,$B$20)+1-ROW('Eingabe Meldungen'!A6)))),"",INDEX('Eingabe Meldungen'!$D$2:$D$492,LARGE(('Eingabe Meldungen'!$A$2:$A$492=$B$20)*(ROW('Eingabe Meldungen'!$A$2:$A$492)-1),COUNTIF('Eingabe Meldungen'!$A$2:$A$492,$B$20)+1-ROW('Eingabe Meldungen'!A6))))} -> Rolf | D27: {=IF(B27<>"",INDEX('Eingabe Meldungen'!$C$2:$H$492,MATCH(B27&C27,'Eingabe Meldungen'!$C$2:$C$492&'Eingabe Meldungen'!$D$2:$D$492,0),6),"")} -> 1950 | E27: {=IF(B27<>"",INDEX('Eingabe Meldungen'!$C$2:$H$492,MATCH(B27&C27,'Eingabe Meldungen'!$C$2:$C$492&'Eingabe Meldungen'!$D$2:$D$492,0),4),"")} -> H | F27: 6 | H27: =RANK(G27,$G$22:$G$51,1) -> #N/A | I27: {=IF(B27<>"",INDEX('Eingabe Meldungen'!$C$2:$J$492,MATCH(B27&C27,'Eingabe Meldungen'!$C$2:$C$492&'Eingabe Meldungen'!$D$2:$D$492,0),8),"")} -> Marbacher Ruderverein
B28: {=IF(ISERROR(INDEX('Eingabe Meldungen'!$C$2:$C$492,LARGE(('Eingabe Meldungen'!$A$2:$A$492=$B$20)*(ROW('Eingabe Meldungen'!$A$2:$A$492)-1),COUNTIF('Eingabe Meldungen'!$A$2:$A$492,$B$20)+1-ROW('Eingabe Meldungen'!A7)))),"",INDEX('Eingabe Meldungen'!$C$2:$C$492,LARGE(('Eingabe Meldungen'!$A$2:$A$492=$B$20)*(ROW('Eingabe Meldungen'!$A$2:$A$492)-1),COUNTIF('Eingabe Meldungen'!$A$2:$A$492,$B$20)+1-ROW('Eingabe Meldungen'!A7))))} -> Rentz | C28: {=IF(ISERROR(INDEX('Eingabe Meldungen'!$D$2:$D$492,LARGE(('Eingabe Meldungen'!$A$2:$A$492=$B$20)*(ROW('Eingabe Meldungen'!$A$2:$A$492)-1),COUNTIF('Eingabe Meldungen'!$A$2:$A$492,$B$20)+1-ROW('Eingabe Meldungen'!A7)))),"",INDEX('Eingabe Meldungen'!$D$2:$D$492,LARGE(('Eingabe Meldungen'!$A$2:$A$492=$B$20)*(ROW('Eingabe Meldungen'!$A$2:$A$492)-1),COUNTIF('Eingabe Meldungen'!$A$2:$A$492,$B$20)+1-ROW('Eingabe Meldungen'!A7))))} -> Jürgen | D28: {=IF(B28<>"",INDEX('Eingabe Meldungen'!$C$2:$H$492,MATCH(B28&C28,'Eingabe Meldungen'!$C$2:$C$492&'Eingabe Meldungen'!$D$2:$D$492,0),6),"")} -> 1955 | E28: {=IF(B28<>"",INDEX('Eingabe Meldungen'!$C$2:$H$492,MATCH(B28&C28,'Eingabe Meldungen'!$C$2:$C$492&'Eingabe Meldungen'!$D$2:$D$492,0),4),"")} -> G | F28: 7 | H28: =RANK(G28,$G$22:$G$51,1) -> #N/A | I28: {=IF(B28<>"",INDEX('Eingabe Meldungen'!$C$2:$J$492,MATCH(B28&C28,'Eingabe Meldungen'!$C$2:$C$492&'Eingabe Meldungen'!$D$2:$D$492,0),8),"")} -> Marbacher Ruderverein
B29: {=IF(ISERROR(INDEX('Eingabe Meldungen'!$C$2:$C$492,LARGE(('Eingabe Meldungen'!$A$2:$A$492=$B$20)*(ROW('Eingabe Meldungen'!$A$2:$A$492)-1),COUNTIF('Eingabe Meldungen'!$A$2:$A$492,$B$20)+1-ROW('Eingabe Meldungen'!A8)))),"",INDEX('Eingabe Meldungen'!$C$2:$C$492,LARGE(('Eingabe Meldungen'!$A$2:$A$492=$B$20)*(ROW('Eingabe Meldungen'!$A$2:$A$492)-1),COUNTIF('Eingabe Meldungen'!$A$2:$A$492,$B$20)+1-ROW('Eingabe Meldungen'!A8))))} -> Klinge | C29: {=IF(ISERROR(INDEX('Eingabe Meldungen'!$D$2:$D$492,LARGE(('Eingabe Meldungen'!$A$2:$A$492=$B$20)*(ROW('Eingabe Meldungen'!$A$2:$A$492)-1),COUNTIF('Eingabe Meldungen'!$A$2:$A$492,$B$20)+1-ROW('Eingabe Meldungen'!A8)))),"",INDEX('Eingabe Meldungen'!$D$2:$D$492,LARGE(('Eingabe Meldungen'!$A$2:$A$492=$B$20)*(ROW('Eingabe Meldungen'!$A$2:$A$492)-1),COUNTIF('Eingabe Meldungen'!$A$2:$A$492,$B$20)+1-ROW('Eingabe Meldungen'!A8))))} -> Achim | D29: {=IF(B29<>"",INDEX('Eingabe Meldungen'!$C$2:$H$492,MATCH(B29&C29,'Eingabe Meldungen'!$C$2:$C$492&'Eingabe Meldungen'!$D$2:$D$492,0),6),"")} -> 1957 | E29: {=IF(B29<>"",INDEX('Eingabe Meldungen'!$C$2:$H$492,MATCH(B29&C29,'Eingabe Meldungen'!$C$2:$C$492&'Eingabe Meldungen'!$D$2:$D$492,0),4),"")} -> F | F29: 8 | H29: =RANK(G29,$G$22:$G$51,1) -> #N/A | I29: {=IF(B29<>"",INDEX('Eingabe Meldungen'!$C$2:$J$492,MATCH(B29&C29,'Eingabe Meldungen'!$C$2:$C$492&'Eingabe Meldungen'!$D$2:$D$492,0),8),"")} -> SSG Bensheim
B30: {=IF(ISERROR(INDEX('Eingabe Meldungen'!$C$2:$C$492,LARGE(('Eingabe Meldungen'!$A$2:$A$492=$B$20)*(ROW('Eingabe Meldungen'!$A$2:$A$492)-1),COUNTIF('Eingabe Meldungen'!$A$2:$A$492,$B$20)+1-ROW('Eingabe Meldungen'!A9)))),"",INDEX('Eingabe Meldungen'!$C$2:$C$492,LARGE(('Eingabe Meldungen'!$A$2:$A$492=$B$20)*(ROW('Eingabe Meldungen'!$A$2:$A$492)-1),COUNTIF('Eingabe Meldungen'!$A$2:$A$492,$B$20)+1-ROW('Eingabe Meldungen'!A9))))} -> Köhler | C30: {=IF(ISERROR(INDEX('Eingabe Meldungen'!$D$2:$D$492,LARGE(('Eingabe Meldungen'!$A$2:$A$492=$B$20)*(ROW('Eingabe Meldungen'!$A$2:$A$492)-1),COUNTIF('Eingabe Meldungen'!$A$2:$A$492,$B$20)+1-ROW('Eingabe Meldungen'!A9)))),"",INDEX('Eingabe Meldungen'!$D$2:$D$492,LARGE(('Eingabe Meldungen'!$A$2:$A$492=$B$20)*(ROW('Eingabe Meldungen'!$A$2:$A$492)-1),COUNTIF('Eingabe Meldungen'!$A$2:$A$492,$B$20)+1-ROW('Eingabe Meldungen'!A9))))} -> Bernhard | D30: {=IF(B30<>"",INDEX('Eingabe Meldungen'!$C$2:$H$492,MATCH(B30&C30,'Eingabe Meldungen'!$C$2:$C$492&'Eingabe Meldungen'!$D$2:$D$492,0),6),"")} -> 1958 | E30: {=IF(B30<>"",INDEX('Eingabe Meldungen'!$C$2:$H$492,MATCH(B30&C30,'Eingabe Meldungen'!$C$2:$C$492&'Eingabe Meldungen'!$D$2:$D$492,0),4),"")} -> F | F30: 9 | H30: =RANK(G30,$G$22:$G$51,1) -> #N/A | I30: {=IF(B30<>"",INDEX('Eingabe Meldungen'!$C$2:$J$492,MATCH(B30&C30,'Eingabe Meldungen'!$C$2:$C$492&'Eingabe Meldungen'!$D$2:$D$492,0),8),"")} -> Fitness Oase in Regen
B31: {=IF(ISERROR(INDEX('Eingabe Meldungen'!$C$2:$C$492,LARGE(('Eingabe Meldungen'!$A$2:$A$492=$B$20)*(ROW('Eingabe Meldungen'!$A$2:$A$492)-1),COUNTIF('Eingabe Meldungen'!$A$2:$A$492,$B$20)+1-ROW('Eingabe Meldungen'!A10)))),"",INDEX('Eingabe Meldungen'!$C$2:$C$492,LARGE(('Eingabe Meldungen'!$A$2:$A$492=$B$20)*(ROW('Eingabe Meldungen'!$A$2:$A$492)-1),COUNTIF('Eingabe Meldungen'!$A$2:$A$492,$B$20)+1-ROW('Eingabe Meldungen'!A10))))} -> Schuhn | C31: {=IF(ISERROR(INDEX('Eingabe Meldungen'!$D$2:$D$492,LARGE(('Eingabe Meldungen'!$A$2:$A$492=$B$20)*(ROW('Eingabe Meldungen'!$A$2:$A$492)-1),COUNTIF('Eingabe Meldungen'!$A$2:$A$492,$B$20)+1-ROW('Eingabe Meldungen'!A10)))),"",INDEX('Eingabe Meldungen'!$D$2:$D$492,LARGE(('Eingabe Meldungen'!$A$2:$A$492=$B$20)*(ROW('Eingabe Meldungen'!$A$2:$A$492)-1),COUNTIF('Eingabe Meldungen'!$A$2:$A$492,$B$20)+1-ROW('Eingabe Meldungen'!A10))))} -> Peter | D31: {=IF(B31<>"",INDEX('Eingabe Meldungen'!$C$2:$H$492,MATCH(B31&C31,'Eingabe Meldungen'!$C$2:$C$492&'Eingabe Meldungen'!$D$2:$D$492,0),6),"")} -> 1959 | E31: {=IF(B31<>"",INDEX('Eingabe Meldungen'!$C$2:$H$492,MATCH(B31&C31,'Eingabe Meldungen'!$C$2:$C$492&'Eingabe Meldungen'!$D$2:$D$492,0),4),"")} -> F | F31: 10 | H31: =RANK(G31,$G$22:$G$51,1) -> #N/A | I31: {=IF(B31<>"",INDEX('Eingabe Meldungen'!$C$2:$J$492,MATCH(B31&C31,'Eingabe Meldungen'!$C$2:$C$492&'Eingabe Meldungen'!$D$2:$D$492,0),8),"")} -> ErgoRudern Saarlouis
B32: {=IF(ISERROR(INDEX('Eingabe Meldungen'!$C$2:$C$492,LARGE(('Eingabe Meldungen'!$A$2:$A$492=$B$20)*(ROW('Eingabe Meldungen'!$A$2:$A$492)-1),COUNTIF('Eingabe Meldungen'!$A$2:$A$492,$B$20)+1-ROW('Eingabe Meldungen'!A11)))),"",INDEX('Eingabe Meldungen'!$C$2:$C$492,LARGE(('Eingabe Meldungen'!$A$2:$A$492=$B$20)*(ROW('Eingabe Meldungen'!$A$2:$A$492)-1),COUNTIF('Eingabe Meldungen'!$A$2:$A$492,$B$20)+1-ROW('Eingabe Meldungen'!A11))))} -> Marx | C32: {=IF(ISERROR(INDEX('Eingabe Meldungen'!$D$2:$D$492,LARGE(('Eingabe Meldungen'!$A$2:$A$492=$B$20)*(ROW('Eingabe Meldungen'!$A$2:$A$492)-1),COUNTIF('Eingabe Meldungen'!$A$2:$A$492,$B$20)+1-ROW('Eingabe Meldungen'!A11)))),"",INDEX('Eingabe Meldungen'!$D$2:$D$492,LARGE(('Eingabe Meldungen'!$A$2:$A$492=$B$20)*(ROW('Eingabe Meldungen'!$A$2:$A$492)-1),COUNTIF('Eingabe Meldungen'!$A$2:$A$492,$B$20)+1-ROW('Eingabe Meldungen'!A11))))} -> Johannes | D32: {=IF(B32<>"",INDEX('Eingabe Meldungen'!$C$2:$H$492,MATCH(B32&C32,'Eingabe Meldungen'!$C$2:$C$492&'Eingabe Meldungen'!$D$2:$D$492,0),6),"")} -> 1962 | E32: {=IF(B32<>"",INDEX('Eingabe Meldungen'!$C$2:$H$492,MATCH(B32&C32,'Eingabe Meldungen'!$C$2:$C$492&'Eingabe Meldungen'!$D$2:$D$492,0),4),"")} -> E | F32: 11 | H32: =RANK(G32,$G$22:$G$51,1) -> #N/A | I32: {=IF(B32<>"",INDEX('Eingabe Meldungen'!$C$2:$J$492,MATCH(B32&C32,'Eingabe Meldungen'!$C$2:$C$492&'Eingabe Meldungen'!$D$2:$D$492,0),8),"")} -> RC Neptun Neckarelz | K32: A2
B33: {=IF(ISERROR(INDEX('Eingabe Meldungen'!$C$2:$C$492,LARGE(('Eingabe Meldungen'!$A$2:$A$492=$B$20)*(ROW('Eingabe Meldungen'!$A$2:$A$492)-1),COUNTIF('Eingabe Meldungen'!$A$2:$A$492,$B$20)+1-ROW('Eingabe Meldungen'!A12)))),"",INDEX('Eingabe Meldungen'!$C$2:$C$492,LARGE(('Eingabe Meldungen'!$A$2:$A$492=$B$20)*(ROW('Eingabe Meldungen'!$A$2:$A$492)-1),COUNTIF('Eingabe Meldungen'!$A$2:$A$492,$B$20)+1-ROW('Eingabe Meldungen'!A12))))} -> Reinert | C33: {=IF(ISERROR(INDEX('Eingabe Meldungen'!$D$2:$D$492,LARGE(('Eingabe Meldungen'!$A$2:$A$492=$B$20)*(ROW('Eingabe Meldungen'!$A$2:$A$492)-1),COUNTIF('Eingabe Meldungen'!$A$2:$A$492,$B$20)+1-ROW('Eingabe Meldungen'!A12)))),"",INDEX('Eingabe Meldungen'!$D$2:$D$492,LARGE(('Eingabe Meldungen'!$A$2:$A$492=$B$20)*(ROW('Eingabe Meldungen'!$A$2:$A$492)-1),COUNTIF('Eingabe Meldungen'!$A$2:$A$492,$B$20)+1-ROW('Eingabe Meldungen'!A12))))} -> Gerhard | D33: {=IF(B33<>"",INDEX('Eingabe Meldungen'!$C$2:$H$492,MATCH(B33&C33,'Eingabe Meldungen'!$C$2:$C$492&'Eingabe Meldungen'!$D$2:$D$492,0),6),"")} -> 1964 | E33: {=IF(B33<>"",INDEX('Eingabe Meldungen'!$C$2:$H$492,MATCH(B33&C33,'Eingabe Meldungen'!$C$2:$C$492&'Eingabe Meldungen'!$D$2:$D$492,0),4),"")} -> E | F33: 12 | H33: =RANK(G33,$G$22:$G$51,1) -> #N/A | I33: {=IF(B33<>"",INDEX('Eingabe Meldungen'!$C$2:$J$492,MATCH(B33&C33,'Eingabe Meldungen'!$C$2:$C$492&'Eingabe Meldungen'!$D$2:$D$492,0),8),"")} -> HRG Schwaben
B34: {=IF(ISERROR(INDEX('Eingabe Meldungen'!$C$2:$C$492,LARGE(('Eingabe Meldungen'!$A$2:$A$492=$B$20)*(ROW('Eingabe Meldungen'!$A$2:$A$492)-1),COUNTIF('Eingabe Meldungen'!$A$2:$A$492,$B$20)+1-ROW('Eingabe Meldungen'!A13)))),"",INDEX('Eingabe Meldungen'!$C$2:$C$492,LARGE(('Eingabe Meldungen'!$A$2:$A$492=$B$20)*(ROW('Eingabe Meldungen'!$A$2:$A$492)-1),COUNTIF('Eingabe Meldungen'!$A$2:$A$492,$B$20)+1-ROW('Eingabe Meldungen'!A13))))} -> Marion | C34: {=IF(ISERROR(INDEX('Eingabe Meldungen'!$D$2:$D$492,LARGE(('Eingabe Meldungen'!$A$2:$A$492=$B$20)*(ROW('Eingabe Meldungen'!$A$2:$A$492)-1),COUNTIF('Eingabe Meldungen'!$A$2:$A$492,$B$20)+1-ROW('Eingabe Meldungen'!A13)))),"",INDEX('Eingabe Meldungen'!$D$2:$D$492,LARGE(('Eingabe Meldungen'!$A$2:$A$492=$B$20)*(ROW('Eingabe Meldungen'!$A$2:$A$492)-1),COUNTIF('Eingabe Meldungen'!$A$2:$A$492,$B$20)+1-ROW('Eingabe Meldungen'!A13))))} -> Markus | D34: {=IF(B34<>"",INDEX('Eingabe Meldungen'!$C$2:$H$492,MATCH(B34&C34,'Eingabe Meldungen'!$C$2:$C$492&'Eingabe Meldungen'!$D$2:$D$492,0),6),"")} -> 1966 | E34: {=IF(B34<>"",INDEX('Eingabe Meldungen'!$C$2:$H$492,MATCH(B34&C34,'Eingabe Meldungen'!$C$2:$C$492&'Eingabe Meldungen'!$D$2:$D$492,0),4),"")} -> D | F34: 13 | H34: =RANK(G34,$G$22:$G$51,1) -> #N/A | I34: {=IF(B34<>"",INDEX('Eingabe Meldungen'!$C$2:$J$492,MATCH(B34&C34,'Eingabe Meldungen'!$C$2:$C$492&'Eingabe Meldungen'!$D$2:$D$492,0),8),"")} -> ErgoRudern Saarlouis
B35: {=IF(ISERROR(INDEX('Eingabe Meldungen'!$C$2:$C$492,LARGE(('Eingabe Meldungen'!$A$2:$A$492=$B$20)*(ROW('Eingabe Meldungen'!$A$2:$A$492)-1),COUNTIF('Eingabe Meldungen'!$A$2:$A$492,$B$20)+1-ROW('Eingabe Meldungen'!A14)))),"",INDEX('Eingabe Meldungen'!$C$2:$C$492,LARGE(('Eingabe Meldungen'!$A$2:$A$492=$B$20)*(ROW('Eingabe Meldungen'!$A$2:$A$492)-1),COUNTIF('Eingabe Meldungen'!$A$2:$A$492,$B$20)+1-ROW('Eingabe Meldungen'!A14))))} -> Grünewald | C35: {=IF(ISERROR(INDEX('Eingabe Meldungen'!$D$2:$D$492,LARGE(('Eingabe Meldungen'!$A$2:$A$492=$B$20)*(ROW('Eingabe Meldungen'!$A$2:$A$492)-1),COUNTIF('Eingabe Meldungen'!$A$2:$A$492,$B$20)+1-ROW('Eingabe Meldungen'!A14)))),"",INDEX('Eingabe Meldungen'!$D$2:$D$492,LARGE(('Eingabe Meldungen'!$A$2:$A$492=$B$20)*(ROW('Eingabe Meldungen'!$A$2:$A$492)-1),COUNTIF('Eingabe Meldungen'!$A$2:$A$492,$B$20)+1-ROW('Eingabe Meldungen'!A14))))} -> Christoph | D35: {=IF(B35<>"",INDEX('Eingabe Meldungen'!$C$2:$H$492,MATCH(B35&C35,'Eingabe Meldungen'!$C$2:$C$492&'Eingabe Meldungen'!$D$2:$D$492,0),6),"")} -> 1968 | E35: {=IF(B35<>"",INDEX('Eingabe Meldungen'!$C$2:$H$492,MATCH(B35&C35,'Eingabe Meldungen'!$C$2:$C$492&'Eingabe Meldungen'!$D$2:$D$492,0),4),"")} -> D | F35: 14 | H35: =RANK(G35,$G$22:$G$51,1) -> #N/A | I35: {=IF(B35<>"",INDEX('Eingabe Meldungen'!$C$2:$J$492,MATCH(B35&C35,'Eingabe Meldungen'!$C$2:$C$492&'Eingabe Meldungen'!$D$2:$D$492,0),8),"")} -> Marbacher Ruderverein
